(dp1
S'output'
p2
S'<type \'exceptions.RuntimeError\'> Failure to connect, tried 5 times:\nTraceback (most recent call last):\n  File "/home/leotms/Desktop/Sistemas/gluon/packages/dal/pydal/base.py", line 446, in __init__\n    self._adapter = ADAPTERS[self._dbname](**kwargs)\n  File "/home/leotms/Desktop/Sistemas/gluon/packages/dal/pydal/adapters/base.py", line 60, in __call__\n    obj = super(AdapterMeta, cls).__call__(*args, **kwargs)\n  File "/home/leotms/Desktop/Sistemas/gluon/packages/dal/pydal/adapters/mysql.py", line 132, in __init__\n    if do_connect: self.reconnect()\n  File "/home/leotms/Desktop/Sistemas/gluon/packages/dal/pydal/connection.py", line 104, in reconnect\n    self.connection = f()\n  File "/home/leotms/Desktop/Sistemas/gluon/packages/dal/pydal/adapters/mysql.py", line 130, in connector\n    return self.driver.connect(**driver_args)\n  File "/home/leotms/Desktop/Sistemas/gluon/contrib/pymysql/__init__.py", line 93, in Connect\n    return Connection(*args, **kwargs)\n  File "/home/leotms/Desktop/Sistemas/gluon/contrib/pymysql/connections.py", line 575, in __init__\n    self._connect()\n  File "/home/leotms/Desktop/Sistemas/gluon/contrib/pymysql/connections.py", line 743, in _connect\n    raise OperationalError(2003, "Can\'t connect to MySQL server on %r (%s)" % (self.host, e.args[0]))\nOperationalError: (2003, "Can\'t connect to MySQL server on \'localhost\' (111)")\n'
p3
sS'layer'
p4
S'/home/leotms/Desktop/Sistemas/applications/SPE/models/dbSPE.py'
p5
sS'code'
p6
S"# -*- coding: utf-8 -*-\ndbSPE = DAL('mysql://root:root@localhost:3306/pasantiasnuevo', pool_size=0,migrate=False)\n"
p7
sS'snapshot'
p8
(dp9
sS'traceback'
p10
S'Traceback (most recent call last):\n  File "/home/leotms/Desktop/Sistemas/gluon/restricted.py", line 227, in restricted\n    exec ccode in environment\n  File "/home/leotms/Desktop/Sistemas/applications/SPE/models/dbSPE.py", line 2, in <module>\n    dbSPE = DAL(\'mysql://root:root@localhost:3306/pasantiasnuevo\', pool_size=0,migrate=False)\n  File "/home/leotms/Desktop/Sistemas/gluon/packages/dal/pydal/base.py", line 174, in __call__\n    obj = super(MetaDAL, cls).__call__(*args, **kwargs)\n  File "/home/leotms/Desktop/Sistemas/gluon/packages/dal/pydal/base.py", line 473, in __init__\n    "Failure to connect, tried %d times:\\n%s" % (attempts, tb)\nRuntimeError: Failure to connect, tried 5 times:\nTraceback (most recent call last):\n  File "/home/leotms/Desktop/Sistemas/gluon/packages/dal/pydal/base.py", line 446, in __init__\n    self._adapter = ADAPTERS[self._dbname](**kwargs)\n  File "/home/leotms/Desktop/Sistemas/gluon/packages/dal/pydal/adapters/base.py", line 60, in __call__\n    obj = super(AdapterMeta, cls).__call__(*args, **kwargs)\n  File "/home/leotms/Desktop/Sistemas/gluon/packages/dal/pydal/adapters/mysql.py", line 132, in __init__\n    if do_connect: self.reconnect()\n  File "/home/leotms/Desktop/Sistemas/gluon/packages/dal/pydal/connection.py", line 104, in reconnect\n    self.connection = f()\n  File "/home/leotms/Desktop/Sistemas/gluon/packages/dal/pydal/adapters/mysql.py", line 130, in connector\n    return self.driver.connect(**driver_args)\n  File "/home/leotms/Desktop/Sistemas/gluon/contrib/pymysql/__init__.py", line 93, in Connect\n    return Connection(*args, **kwargs)\n  File "/home/leotms/Desktop/Sistemas/gluon/contrib/pymysql/connections.py", line 575, in __init__\n    self._connect()\n  File "/home/leotms/Desktop/Sistemas/gluon/contrib/pymysql/connections.py", line 743, in _connect\n    raise OperationalError(2003, "Can\'t connect to MySQL server on %r (%s)" % (self.host, e.args[0]))\nOperationalError: (2003, "Can\'t connect to MySQL server on \'localhost\' (111)")\n\n'
p11
s.