(dp1
S'output'
p2
S'<type \'exceptions.RuntimeError\'> Failure to connect, tried 5 times:\nTraceback (most recent call last):\n  File "/home/andres/Documents/internships/gluon/packages/dal/pydal/base.py", line 446, in __init__\n    self._adapter = ADAPTERS[self._dbname](**kwargs)\n  File "/home/andres/Documents/internships/gluon/packages/dal/pydal/adapters/base.py", line 60, in __call__\n    obj = super(AdapterMeta, cls).__call__(*args, **kwargs)\n  File "/home/andres/Documents/internships/gluon/packages/dal/pydal/adapters/mysql.py", line 132, in __init__\n    if do_connect: self.reconnect()\n  File "/home/andres/Documents/internships/gluon/packages/dal/pydal/connection.py", line 104, in reconnect\n    self.connection = f()\n  File "/home/andres/Documents/internships/gluon/packages/dal/pydal/adapters/mysql.py", line 130, in connector\n    return self.driver.connect(**driver_args)\n  File "/home/andres/Documents/internships/gluon/contrib/pymysql/__init__.py", line 93, in Connect\n    return Connection(*args, **kwargs)\n  File "/home/andres/Documents/internships/gluon/contrib/pymysql/connections.py", line 575, in __init__\n    self._connect()\n  File "/home/andres/Documents/internships/gluon/contrib/pymysql/connections.py", line 741, in _connect\n    self._request_authentication()\n  File "/home/andres/Documents/internships/gluon/contrib/pymysql/connections.py", line 796, in _request_authentication\n    self._send_authentication()\n  File "/home/andres/Documents/internships/gluon/contrib/pymysql/connections.py", line 845, in _send_authentication\n    auth_packet.check_error()\n  File "/home/andres/Documents/internships/gluon/contrib/pymysql/connections.py", line 341, in check_error\n    raise_mysql_exception(self.__data)\n  File "/home/andres/Documents/internships/gluon/contrib/pymysql/err.py", line 142, in raise_mysql_exception\n    _check_mysql_exception(errinfo)\n  File "/home/andres/Documents/internships/gluon/contrib/pymysql/err.py", line 135, in _check_mysql_exception\n    raise errorclass, (errno,errorvalue)\nOperationalError: (1045, u"Access denied for user \'root\'@\'localhost\' (using password: YES)")\n'
p3
sS'layer'
p4
S'/home/andres/Documents/internships/applications/SPE/models/dbSPE.py'
p5
sS'code'
p6
S"# -*- coding: utf-8 -*-\ndbSPE = DAL('mysql://root:root@localhost:3306/pasantiasnuevo', pool_size=0,migrate=False)\n"
p7
sS'snapshot'
p8
(dp9
sS'traceback'
p10
S'Traceback (most recent call last):\n  File "/home/andres/Documents/internships/gluon/restricted.py", line 227, in restricted\n    exec ccode in environment\n  File "/home/andres/Documents/internships/applications/SPE/models/dbSPE.py", line 2, in <module>\n  File "/home/andres/Documents/internships/gluon/packages/dal/pydal/base.py", line 174, in __call__\n    obj = super(MetaDAL, cls).__call__(*args, **kwargs)\n  File "/home/andres/Documents/internships/gluon/packages/dal/pydal/base.py", line 473, in __init__\n    "Failure to connect, tried %d times:\\n%s" % (attempts, tb)\nRuntimeError: Failure to connect, tried 5 times:\nTraceback (most recent call last):\n  File "/home/andres/Documents/internships/gluon/packages/dal/pydal/base.py", line 446, in __init__\n    self._adapter = ADAPTERS[self._dbname](**kwargs)\n  File "/home/andres/Documents/internships/gluon/packages/dal/pydal/adapters/base.py", line 60, in __call__\n    obj = super(AdapterMeta, cls).__call__(*args, **kwargs)\n  File "/home/andres/Documents/internships/gluon/packages/dal/pydal/adapters/mysql.py", line 132, in __init__\n    if do_connect: self.reconnect()\n  File "/home/andres/Documents/internships/gluon/packages/dal/pydal/connection.py", line 104, in reconnect\n    self.connection = f()\n  File "/home/andres/Documents/internships/gluon/packages/dal/pydal/adapters/mysql.py", line 130, in connector\n    return self.driver.connect(**driver_args)\n  File "/home/andres/Documents/internships/gluon/contrib/pymysql/__init__.py", line 93, in Connect\n    return Connection(*args, **kwargs)\n  File "/home/andres/Documents/internships/gluon/contrib/pymysql/connections.py", line 575, in __init__\n    self._connect()\n  File "/home/andres/Documents/internships/gluon/contrib/pymysql/connections.py", line 741, in _connect\n    self._request_authentication()\n  File "/home/andres/Documents/internships/gluon/contrib/pymysql/connections.py", line 796, in _request_authentication\n    self._send_authentication()\n  File "/home/andres/Documents/internships/gluon/contrib/pymysql/connections.py", line 845, in _send_authentication\n    auth_packet.check_error()\n  File "/home/andres/Documents/internships/gluon/contrib/pymysql/connections.py", line 341, in check_error\n    raise_mysql_exception(self.__data)\n  File "/home/andres/Documents/internships/gluon/contrib/pymysql/err.py", line 142, in raise_mysql_exception\n    _check_mysql_exception(errinfo)\n  File "/home/andres/Documents/internships/gluon/contrib/pymysql/err.py", line 135, in _check_mysql_exception\n    raise errorclass, (errno,errorvalue)\nOperationalError: (1045, u"Access denied for user \'root\'@\'localhost\' (using password: YES)")\n\n'
p11
s.